<mujoco>
    <option timestep="0.0002" />
    <actuator>
        <motor gear="10000" joint="hinge_1" name="actuator_motor" ctrlrange="-300 300" ctrllimited="true"/>
    </actuator>
    <asset>
        <material name="blue_" rgba="0 0 1 1" />
        <material name="green" rgba="0 1 0 1" />
        <material name="red__" rgba="1 0 0 1" />
        <material name="white" rgba="1 1 1 1" />
    </asset>
    <worldbody>
        <geom type="plane" size="10 10 0.1" pos="0 0 -10" rgba=".9 0 0 1" />
        <light diffuse=".5 .5 .5" pos="0 0 3" dir="0 0 -1" />
        <body>
            <geom type="cylinder" size="0.396 0.2" pos="0 0 2" euler="90 0 0" material="green" />
            <body>
                <geom type="box" size="0.15 2 0.35" pos="0.75 0 0" euler="0 70 90" material="red__"/>
                <body name="link_1" pos="0 0 0">
                    <geom type="cylinder" size="0.396 0.2" pos="1.5 0 -2" euler="90 0 0" material="green" />
                    <inertial pos="1.5 0 -2" mass="0.02"/>
                    <joint/>
                    <body>
                        <geom type="box" size="0.15 2 0.35" pos="1.5 0 -4" euler="90 90 0" material="red__"/>
                        <body>
                            <geom type="cylinder" size="0.396 0.2" pos="1.5 0 -6" euler="90 0 0" material="green" />
                            <inertial pos="1.5 0 -6" mass="0.02"/>
                            <joint name="hinge_1" pos="0 0 0" axis="1 0 0" />
                        </body>
                    </body>
                </body>
            </body>
            <body>
                <geom type="box" size="0.15 2 0.35" pos="-0.75 0 0" euler="0 110 90" material="red__"/>
                <body name="link_2">
                    <geom type="cylinder" size="0.396 0.2" pos="-1.5 0 -2" euler="90 0 0" material="green" />
                    <inertial pos="-1.5 0 -2" mass="0.02"/>
                    <joint/>
                    <body>
                        <geom type="box" size="0.15 2 0.35" pos="-1.5 0 -4" euler="90 90 0" material="red__"/>
                        <body>
                            <geom type="cylinder" size="0.396 0.2" pos="-1.5 0 -6" euler="90 0 0" material="green" />
                            <inertial pos="-1.5 0 -6" mass="0.02"/>
                             <joint name="hinge_2" pos="0 0 0" axis="1 0 0" />
                        </body>
                    </body>
                </body>
            </body>
        </body>
    </worldbody>
    <equality>
        <connect name="kinematic_link" active="false" body1="link_1" body2="link_2" anchor="0 0 4"/>
    </equality>
</mujoco>