<?xml version="1.0" ?>
<robot name="arc">

<mujoco>
  <compiler balanceinertia="true" discardvisual="false" meshdir="meshes" fusestatic="false"/>
</mujoco>

<link name="base_link">
  <inertial>
    <origin xyz="-0.0003364447076081632 0.00040115720688868275 0.0024997648564067886" rpy="0 0 0"/>
    <mass value="0.06603876305121438"/>
    <inertia ixx="8.027486854571549e-05" iyy="7.516784273924607e-05" izz="0.00015516069398884138" ixy="3.72021501890899e-07" iyz="9.65651787516761e-10" ixz="-4.939374084656955e-09"/>
  </inertial>
  <visual>
    <origin xyz="0 0 0" rpy="0 0 0"/>
    <geometry>
      <mesh filename="meshes/base_link.stl" scale="0.001 0.001 0.001"/>
    </geometry>
  </visual>
  <collision>
    <origin xyz="0 0 0" rpy="0 0 0"/>
    <geometry>
      <mesh filename="meshes/base_link.stl" scale="0.001 0.001 0.001"/>
    </geometry>
  </collision>
</link>

<link name="arc_link1">
  <inertial>
    <origin xyz="-0.03742147395297951 0.01672391582074876 -3.461012190644503e-06" rpy="0 0 0"/>
    <mass value="0.049208832810973255"/>
    <inertia ixx="2.713089960607127e-05" iyy="1.781221674608023e-05" izz="4.473386487637132e-05" ixy="1.6265247408293757e-05" iyz="7.0180709564262e-09" ixz="-3.0007629906480437e-09"/>
  </inertial>
  <visual>
    <origin xyz="0.001594 0.055 -0.0025" rpy="0 0 0"/>
    <geometry>
      <mesh filename="meshes/arc_link1.stl" scale="0.001 0.001 0.001"/>
    </geometry>
  </visual>
  <collision>
    <origin xyz="0.001594 0.055 -0.0025" rpy="0 0 0"/>
    <geometry>
      <mesh filename="meshes/arc_link1.stl" scale="0.001 0.001 0.001"/>
    </geometry>
  </collision>
</link>

<link name="arcane_link1">
  <inertial>
    <origin xyz="0.011485729425510405 -0.040113489939863224 -2.3296577488082434e-06" rpy="0 0 0"/>
    <mass value="0.04920883281097323"/>
    <inertia ixx="3.848727755066798e-05" iyy="6.86203946856175e-06" izz="4.514002700203935e-05" ixy="-6.418425206756039e-06" iyz="-3.775383634762923e-09" ixz="-1.4896502626575547e-09"/>
  </inertial>
  <visual>
    <origin xyz="-0.043578 -0.036502 -0.002409" rpy="0 0 0"/>
    <geometry>
      <mesh filename="meshes/arcane_link1.stl" scale="0.001 0.001 0.001"/>
    </geometry>
  </visual>
  <collision>
    <origin xyz="-0.043578 -0.036502 -0.002409" rpy="0 0 0"/>
    <geometry>
      <mesh filename="meshes/arcane_link1.stl" scale="0.001 0.001 0.001"/>
    </geometry>
  </collision>
</link>

<link name="link_arc1">
  <inertial>
    <origin xyz="0.025736632483593157 0.016433811959899285 -8.209172762928003e-06" rpy="0 0 0"/>
    <mass value="0.03271545421444557"/>
    <inertia ixx="2.3130093936672436e-06" iyy="1.5662097173553723e-05" izz="1.7834433450846863e-05" ixy="-4.777124738231837e-06" iyz="1.099780970881366e-09" ixz="9.4380019288997e-09"/>
  </inertial>
  <visual>
    <origin xyz="0.043787 -0.033352 -0.002559" rpy="0 0 0"/>
    <geometry>
      <mesh filename="meshes/link_arc1.stl" scale="0.001 0.001 0.001"/>
    </geometry>
  </visual>
  <collision>
    <origin xyz="0.043787 -0.033352 -0.002559" rpy="0 0 0"/>
    <geometry>
      <mesh filename="meshes/link_arc1.stl" scale="0.001 0.001 0.001"/>
    </geometry>
  </collision>
</link>

<link name="down1">
  <inertial>
    <origin xyz="0.023712169183123216 1.7870360218549992e-05 -0.03640453245358393" rpy="0 0 0"/>
    <mass value="0.09880302057883875"/>
    <inertia ixx="4.859986746304671e-05" iyy="0.00010881515090668977" izz="6.188453100361839e-05" ixy="-7.723787057957491e-08" iyz="3.908030290352167e-08" ixz="4.678054894635137e-05"/>
  </inertial>
  <visual>
    <origin xyz="0.061635 -0.002931 -0.002673" rpy="0 0 0"/>
    <geometry>
      <mesh filename="meshes/down1.stl" scale="0.001 0.001 0.001"/>
    </geometry>
  </visual>
  <collision>
    <origin xyz="0.061635 -0.002931 -0.002673" rpy="0 0 0"/>
    <geometry>
      <mesh filename="meshes/down1.stl" scale="0.001 0.001 0.001"/>
    </geometry>
  </collision>
</link>

<link name="linkvn1">
  <inertial>
    <origin xyz="-0.00515933305878501 -0.020223227736010284 -0.029316404973139025" rpy="0 0 0"/>
    <mass value="0.07753994585247508"/>
    <inertia ixx="6.80003319208347e-05" iyy="3.170909303782578e-05" izz="4.092365286040018e-05" ixy="-7.932805086282313e-06" iyz="-2.934297117443266e-05" ixz="-6.120403130175616e-06"/>
  </inertial>
  <visual>
    <origin xyz="-0.018544 -0.059988 -0.002815" rpy="0 0 0"/>
    <geometry>
      <mesh filename="meshes/linkvn1.stl" scale="0.001 0.001 0.001"/>
    </geometry>
  </visual>
  <collision>
    <origin xyz="-0.018544 -0.059988 -0.002815" rpy="0 0 0"/>
    <geometry>
      <mesh filename="meshes/linkvn1.stl" scale="0.001 0.001 0.001"/>
    </geometry>
  </collision>
</link>

<link name="downlink1">
  <inertial>
    <origin xyz="0.07601117684787717 0.08009545668556628 -0.026594366098090322" rpy="0 0 0"/>
    <mass value="0.09383696393728601"/>
    <inertia ixx="6.479676647612051e-05" iyy="5.733032766924522e-05" izz="8.037117810003226e-05" ixy="3.921778515506852e-05" iyz="2.3628563562819378e-05" ixz="-2.1484156800949394e-05"/>
  </inertial>
  <visual>
    <origin xyz="0.052709 0.101944 -0.002921" rpy="0 0 0"/>
    <geometry>
      <mesh filename="meshes/downlink1.stl" scale="0.001 0.001 0.001"/>
    </geometry>
  </visual>
  <collision>
    <origin xyz="0.052709 0.101944 -0.002921" rpy="0 0 0"/>
    <geometry>
      <mesh filename="meshes/downlink1.stl" scale="0.001 0.001 0.001"/>
    </geometry>
  </collision>
</link>

<link name="cyl1">
  <inertial>
    <origin xyz="8.81523297088958e-05 -0.00013360822607371347 -0.0025003509105911495" rpy="0 0 0"/>
    <mass value="0.011837521118726317"/>
    <inertia ixx="3.2715272535276926e-07" iyy="3.3014236277977997e-07" izz="6.079720834712195e-07" ixy="-3.482223862859936e-09" iyz="-2.117582368135751e-22" ixz="0.0"/>
  </inertial>
  <visual>
    <origin xyz="-0.005747 -0.001138 0.060827" rpy="0 0 0"/>
    <geometry>
      <mesh filename="meshes/cyl1.stl" scale="0.001 0.001 0.001"/>
    </geometry>
  </visual>
  <collision>
    <origin xyz="-0.005747 -0.001138 0.060827" rpy="0 0 0"/>
    <geometry>
      <mesh filename="meshes/cyl1.stl" scale="0.001 0.001 0.001"/>
    </geometry>
  </collision>
</link>

<joint name="Revolute_39" type="continuous">
  <origin xyz="-0.001594 -0.055 0.0025" rpy="0 0 0"/>
  <parent link="base_link"/>
  <child link="arc_link1"/>
  <axis xyz="-0.0 1.0 0.0"/>
</joint>
<transmission name="Revolute_39_tran">
  <type>transmission_interface/SimpleTransmission</type>
  <joint name="Revolute_39">
    <hardwareInterface>PositionJointInterface</hardwareInterface>
  </joint>
  <actuator name="Revolute_39_actr">
    <hardwareInterface>PositionJointInterface</hardwareInterface>
    <mechanicalReduction>1</mechanicalReduction>
  </actuator>
</transmission>

<joint name="Revolute_40" type="continuous">
  <origin xyz="0.043578 0.036502 0.002409" rpy="0 0 0"/>
  <parent link="base_link"/>
  <child link="arcane_link1"/>
  <axis xyz="-0.740442 -0.672121 0.0"/>
</joint>
<transmission name="Revolute_40_tran">
  <type>transmission_interface/SimpleTransmission</type>
  <joint name="Revolute_40">
    <hardwareInterface>PositionJointInterface</hardwareInterface>
  </joint>
  <actuator name="Revolute_40_actr">
    <hardwareInterface>PositionJointInterface</hardwareInterface>
    <mechanicalReduction>1</mechanicalReduction>
  </actuator>
</transmission>

<joint name="Revolute_41" type="continuous">
  <origin xyz="-0.043787 0.033352 0.002559" rpy="0 0 0"/>
  <parent link="base_link"/>
  <child link="link_arc1"/>
  <axis xyz="0.793303 -0.608827 0.0"/>
</joint>
<transmission name="Revolute_41_tran">
  <type>transmission_interface/SimpleTransmission</type>
  <joint name="Revolute_41">
    <hardwareInterface>PositionJointInterface</hardwareInterface>
  </joint>
  <actuator name="Revolute_41_actr">
    <hardwareInterface>PositionJointInterface</hardwareInterface>
    <mechanicalReduction>1</mechanicalReduction>
  </actuator>
</transmission>

<joint name="Revolute_42" type="continuous">
  <origin xyz="-0.060041 0.057931 0.000173" rpy="0 0 0"/>
  <parent link="arc_link1"/>
  <child link="down1"/>
  <axis xyz="1.0 0.0 0.0"/>
</joint>
<transmission name="Revolute_42_tran">
  <type>transmission_interface/SimpleTransmission</type>
  <joint name="Revolute_42">
    <hardwareInterface>PositionJointInterface</hardwareInterface>
  </joint>
  <actuator name="Revolute_42_actr">
    <hardwareInterface>PositionJointInterface</hardwareInterface>
    <mechanicalReduction>1</mechanicalReduction>
  </actuator>
</transmission>

<joint name="Revolute_45" type="continuous">
  <origin xyz="0.062331 0.026636 0.000256" rpy="0 0 0"/>
  <parent link="link_arc1"/>
  <child link="linkvn1"/>
  <axis xyz="-0.204775 -0.978809 -0.0"/>
</joint>
<transmission name="Revolute_45_tran">
  <type>transmission_interface/SimpleTransmission</type>
  <joint name="Revolute_45">
    <hardwareInterface>PositionJointInterface</hardwareInterface>
  </joint>
  <actuator name="Revolute_45_actr">
    <hardwareInterface>PositionJointInterface</hardwareInterface>
    <mechanicalReduction>1</mechanicalReduction>
  </actuator>
</transmission>

<joint name="Revolute_46" type="continuous">
  <origin xyz="-0.096287 -0.138446 0.000512" rpy="0 0 0"/>
  <parent link="arcane_link1"/>
  <child link="downlink1"/>
  <axis xyz="-0.672121 0.740442 -0.0"/>
</joint>
<transmission name="Revolute_46_tran">
  <type>transmission_interface/SimpleTransmission</type>
  <joint name="Revolute_46">
    <hardwareInterface>PositionJointInterface</hardwareInterface>
  </joint>
  <actuator name="Revolute_46_actr">
    <hardwareInterface>PositionJointInterface</hardwareInterface>
    <mechanicalReduction>1</mechanicalReduction>
  </actuator>
</transmission>

<joint name="Rigid_47" type="fixed">
  <origin xyz="0.067382 -0.001793 -0.0635" rpy="0 0 0"/>
  <parent link="down1"/>
  <child link="cyl1"/>
</joint>

</robot>
